<?xml version="1.0"?>
<robot name="simple_robot">

    <!-- 底盘 -->
    <link name="base_link">
        <visual>
            <origin xyz="0 0 0.05" rpy="0 0 0"/>
            <geometry>
                <box size="0.4 0.2 0.1"/>
            </geometry>
            <material name="blue">
                <color rgba="0 0 1 1"/>
            </material>
        </visual>
        <collision>
            <origin xyz="0 0 0.05" rpy="0 0 0"/>
            <geometry>
                <box size="0.4 0.2 0.1"/>
            </geometry>
        </collision>
        <inertial>
            <mass value="5"/>
            <inertia ixx="0.1" ixy="0" ixz="0" iyy="0.1" iyz="0" izz="0.2"/>
        </inertial>
    </link>

    <!-- 左轮 -->
    <link name="wheel_left_link">
        <visual>
            <origin xyz="0 0 0" rpy="1.5708 0 0"/>
            <geometry>
                <cylinder radius="0.05" length="0.03"/>
            </geometry>
            <material name="gray">
                <color rgba="0.5 0.5 0.5 1"/>
            </material>
        </visual>
        <collision>
            <origin xyz="0 0 0" rpy="1.5708 0 0"/>
            <geometry>
                <cylinder radius="0.05" length="0.03"/>
            </geometry>
        </collision>
        <inertial>
            <mass value="0.5"/>
            <inertia ixx="0.01" ixy="0" ixz="0" iyy="0.01" iyz="0" izz="0.01"/>
        </inertial>
    </link>
    <joint name="wheel_left_joint" type="continuous">
        <origin xyz="0.1 0.115 0" rpy="0 0 0"/>
        <parent link="base_link"/>
        <child link="wheel_left_link"/>
        <axis xyz="0 1 0"/>
    </joint>

    <!-- 右轮 -->
    <link name="wheel_right_link">
        <visual>
            <origin xyz="0 0 0" rpy="1.5708 0 0"/>
            <geometry>
                <cylinder radius="0.05" length="0.03"/>
            </geometry>
            <material name="gray">
                <color rgba="0.5 0.5 0.5 1"/>
            </material>
        </visual>
        <collision>
            <origin xyz="0 0 0" rpy="1.5708 0 0"/>
            <geometry>
                <cylinder radius="0.05" length="0.03"/>
            </geometry>
        </collision>
        <inertial>
            <mass value="0.5"/>
            <inertia ixx="0.01" ixy="0" ixz="0" iyy="0.01" iyz="0" izz="0.01"/>
        </inertial>
    </link>
    <joint name="wheel_right_joint" type="continuous">
        <origin xyz="0.1 -0.115 0" rpy="0 0 0"/>
        <parent link="base_link"/>
        <child link="wheel_right_link"/>
        <axis xyz="0 1 0"/>
    </joint>

    <!-- 万向轮 -->
    <link name="caster_link">
        <visual>
            <origin xyz="0 0 0" rpy="0 0 0"/>
            <geometry>
                <sphere radius="0.03"/>
            </geometry>
            <material name="black">
                <color rgba="0 0 0 1"/>
            </material>
        </visual>
        <collision>
            <origin xyz="0 0 0" rpy="0 0 0"/>
            <geometry>
                <sphere radius="0.03"/>
            </geometry>
        </collision>
        <inertial>
            <mass value="0.2"/>
            <inertia ixx="0.001" ixy="0" ixz="0" iyy="0.001" iyz="0" izz="0.001"/>
        </inertial>
    </link>
    <joint name="caster_joint" type="fixed">
        <origin xyz="-0.18 0 -0.02" rpy="0 0 0"/>
        <parent link="base_link"/>
        <child link="caster_link"/>
    </joint>

    <!-- GAZEBO 差速驱动插件（让小车能跑） -->
    <gazebo>
        <plugin name="diff_drive" filename="libgazebo_ros_diff_drive.so">
            <rosDebugLevel>Debug</rosDebugLevel>
            <publishWheelTF>true</publishWheelTF>
            <publishOdomTF>true</publishOdomTF>
            <robotNamespace>/</robotNamespace>
            <leftJoint>wheel_left_joint</leftJoint>
            <rightJoint>wheel_right_joint</rightJoint>
            <wheelSeparation>0.23</wheelSeparation>
            <wheelDiameter>0.1</wheelDiameter>
            <commandTopic>cmd_vel</commandTopic>
            <odometryTopic>odom</odometryTopic>
            <odometryFrame>odom</odometryFrame>
            <robotBaseFrame>base_link</robotBaseFrame>
        </plugin>
    </gazebo>

</robot>
